<?xml version="1.0" encoding="utf-8"?>
<!-- This URDF was automatically created by SolidWorks to URDF Exporter! Originally created by Stephen Brawner (brawner@gmail.com)
     Commit Version: 1.5.0-0-g9aa0fdb  Build Version: 1.5.7004.21443
     For more information, please see http://wiki.ros.org/sw_urdf_exporter -->
<robot
  name="barabasz">
  <link
    name="MainBoard">
    <inertial>
      <origin
        xyz="0.0320000193091435 0.0395027228412031 -0.00887228498305923"
        rpy="0 0 0" />
      <mass
        value="0.129368445562822" />
      <inertia
        ixx="8.48084091160014E-05"
        ixy="2.93923351652188E-15"
        ixz="2.06187013678502E-15"
        iyy="3.18110038223056E-05"
        iyz="-1.94866907025266E-08"
        izz="0.000114276211083158" />
    </inertial>
    <visual>
      <origin
        xyz="0 0 0"
        rpy="0 0 0" />
      <geometry>
        <mesh
          filename="package://lizardv3_description/meshes/MainBoard.STL" />
      </geometry>
      <material
        name="">
        <color
          rgba="0.92156862745098 0.92156862745098 0.92156862745098 1" />
      </material>
    </visual>
    <collision>
      <origin
        xyz="0 0 0"
        rpy="0 0 0" />
      <geometry>
        <mesh
          filename="package://lizardv3_description/meshes/MainBoard.STL" />
      </geometry>
    </collision>
  </link>
  <link
    name="FRndServoLink">
    <inertial>
      <origin
        xyz="0.00980168634688897 0.00502207563388984 0.00196275735380311"
        rpy="0 0 0" />
      <mass
        value="0.00898215948151009" />
      <inertia
        ixx="5.02863360750936E-07"
        ixy="4.18675151934187E-10"
        ixz="3.94807696352951E-11"
        iyy="3.74381836870733E-07"
        iyz="-1.31121128677089E-07"
        izz="3.05060718459654E-07" />
    </inertial>
    <visual>
      <origin
        xyz="0 0 0"
        rpy="0 0 0" />
      <geometry>
        <mesh
          filename="package://lizardv3_description/meshes/FRndServoLink.STL" />
      </geometry>
      <material
        name="">
        <color
          rgba="0.749019607843137 0.749019607843137 0.749019607843137 1" />
      </material>
    </visual>
    <collision>
      <origin
        xyz="0 0 0"
        rpy="0 0 0" />
      <geometry>
        <mesh
          filename="package://lizardv3_description/meshes/FRndServoLink.STL" />
      </geometry>
    </collision>
  </link>
  <joint
    name="FRndServoJnt"
    type="continuous">
    <origin
      xyz="0.0615 0.087 -0.016"
      rpy="3.1416 0 1.5708" />
    <parent
      link="MainBoard" />
    <child
      link="FRndServoLink" />
    <axis
      xyz="-1 0 0" />
    <safety_controller
      k_velocity="0" />
  </joint>
  <link
    name="FRstArmLink">
    <inertial>
      <origin
        xyz="-0.050087587173191 0.00194912579241757 0.000253934431876823"
        rpy="0 0 0" />
      <mass
        value="0.0107279118401016" />
      <inertia
        ixx="4.12846705736316E-07"
        ixy="-3.43063723092757E-12"
        ixz="7.44940299377242E-12"
        iyy="1.46713624981902E-06"
        iyz="-9.74334437552982E-09"
        izz="1.1962482651399E-06" />
    </inertial>
    <visual>
      <origin
        xyz="0 0 0"
        rpy="0 0 0" />
      <geometry>
        <mesh
          filename="package://lizardv3_description/meshes/FRstArmLink.STL" />
      </geometry>
      <material
        name="">
        <color
          rgba="0.92156862745098 0.92156862745098 0.92156862745098 1" />
      </material>
    </visual>
    <collision>
      <origin
        xyz="0 0 0"
        rpy="0 0 0" />
      <geometry>
        <mesh
          filename="package://lizardv3_description/meshes/FRstArmLink.STL" />
      </geometry>
    </collision>
  </link>
  <joint
    name="FRstArmJnt"
    type="continuous">
    <origin
      xyz="0.01165 0.012199 -0.010432"
      rpy="-1.5708 0.87266 -1.5708" />
    <parent
      link="FRndServoLink" />
    <child
      link="FRstArmLink" />
    <axis
      xyz="0 -1 0" />
    <safety_controller
      k_velocity="0" />
  </joint>
  <link
    name="FRndArmLink">
    <inertial>
      <origin
        xyz="1.66533453693773E-16 0.00400000000000231 0.0271089217366474"
        rpy="0 0 0" />
      <mass
        value="0.0036829203673205" />
      <inertia
        ixx="1.06068205884601E-06"
        ixy="-2.61078880837049E-23"
        ixz="-3.15670781781632E-21"
        iyy="1.0612743799609E-06"
        iyz="-9.53408506083935E-23"
        izz="3.98768050329809E-08" />
    </inertial>
    <visual>
      <origin
        xyz="0 0 0"
        rpy="0 0 0" />
      <geometry>
        <mesh
          filename="package://lizardv3_description/meshes/FRndArmLink.STL" />
      </geometry>
      <material
        name="">
        <color
          rgba="0.92156862745098 0.92156862745098 0.92156862745098 1" />
      </material>
    </visual>
    <collision>
      <origin
        xyz="0 0 0"
        rpy="0 0 0" />
      <geometry>
        <mesh
          filename="package://lizardv3_description/meshes/FRndArmLink.STL" />
      </geometry>
    </collision>
  </link>
  <joint
    name="FRndArmJnt"
    type="continuous">
    <origin
      xyz="-0.0621 0.0150500000002124 0.00515000000000268"
      rpy="1.64274156972154 -1.57079631189374 -1.64274415968957" />
    <parent
      link="FRstArmLink" />
    <child
      link="FRndArmLink" />
    <axis
      xyz="0 -1 0" />
    <safety_controller
      k_velocity="0" />
  </joint>
  <link
    name="FLndServoLink">
    <inertial>
      <origin
        xyz="0.0050221 0.0098014 0.0019628"
        rpy="0 0 0" />
      <mass
        value="0.0089822" />
      <inertia
        ixx="3.7438E-07"
        ixy="4.0384E-10"
        ixz="-1.3112E-07"
        iyy="5.0286E-07"
        iyz="3.248E-11"
        izz="3.0506E-07" />
    </inertial>
    <visual>
      <origin
        xyz="0 0 0"
        rpy="0 0 0" />
      <geometry>
        <mesh
          filename="package://lizardv3_description/meshes/FLndServoLink.STL" />
      </geometry>
      <material
        name="">
        <color
          rgba="1 0.94902 0.9098 1" />
      </material>
    </visual>
    <collision>
      <origin
        xyz="0 0 0"
        rpy="0 0 0" />
      <geometry>
        <mesh
          filename="package://lizardv3_description/meshes/FLndServoLink.STL" />
      </geometry>
    </collision>
  </link>
  <joint
    name="FLndServoJnt"
    type="continuous">
    <origin
      xyz="0.00250000000000065 0.0869999999999997 -0.016"
      rpy="-3.14159265358979 0 3.14159265358979" />
    <parent
      link="MainBoard" />
    <child
      link="FLndServoLink" />
    <axis
      xyz="0 -1 0" />
    <safety_controller
      k_velocity="0" />
  </joint>
  <link
    name="FLstArmLink">
    <inertial>
      <origin
        xyz="-0.0500875873328301 0.00194912587509953 0.000253934473360917"
        rpy="0 0 0" />
      <mass
        value="0.0107279119437584" />
      <inertia
        ixx="4.12846707912603E-07"
        ixy="-3.42949742563357E-12"
        ixz="7.45129949397818E-12"
        iyy="1.46713625367284E-06"
        iyz="-9.74334532607003E-09"
        izz="1.19624826799648E-06" />
    </inertial>
    <visual>
      <origin
        xyz="0 0 0"
        rpy="0 0 0" />
      <geometry>
        <mesh
          filename="package://lizardv3_description/meshes/FLstArmLink.STL" />
      </geometry>
      <material
        name="">
        <color
          rgba="0.92156862745098 0.92156862745098 0.92156862745098 1" />
      </material>
    </visual>
    <collision>
      <origin
        xyz="0 0 0"
        rpy="0 0 0" />
      <geometry>
        <mesh
          filename="package://lizardv3_description/meshes/FLstArmLink.STL" />
      </geometry>
    </collision>
  </link>
  <joint
    name="FLstArmJnt"
    type="continuous">
    <origin
      xyz="0.0121985951706078 0.0116500000000019 -0.0104316478019355"
      rpy="-1.57079632679489 0.872664625997144 3.14159265358978" />
    <parent
      link="FLndServoLink" />
    <child
      link="FLstArmLink" />
    <axis
      xyz="0 -1 0" />
    <safety_controller
      k_velocity="0" />
  </joint>
  <link
    name="FLndArmLink">
    <inertial>
      <origin
        xyz="1.77635683940025E-15 0.00400000000000253 0.0271089217366467"
        rpy="0 0 0" />
      <mass
        value="0.00368292036732051" />
      <inertia
        ixx="1.06068205884601E-06"
        ixy="-1.47083052669585E-23"
        ixz="-2.75851809589364E-22"
        iyy="1.06127437996091E-06"
        iyz="1.81076136779072E-21"
        izz="3.98768050329816E-08" />
    </inertial>
    <visual>
      <origin
        xyz="0 0 0"
        rpy="0 0 0" />
      <geometry>
        <mesh
          filename="package://lizardv3_description/meshes/FLndArmLink.STL" />
      </geometry>
      <material
        name="">
        <color
          rgba="0.92156862745098 0.92156862745098 0.92156862745098 1" />
      </material>
    </visual>
    <collision>
      <origin
        xyz="0 0 0"
        rpy="0 0 0" />
      <geometry>
        <mesh
          filename="package://lizardv3_description/meshes/FLndArmLink.STL" />
      </geometry>
    </collision>
  </link>
  <joint
    name="FLndArmJnt"
    type="continuous">
    <origin
      xyz="-0.0621 0.01505 0.00515"
      rpy="-1.9544 -1.5708 1.9544" />
    <parent
      link="FLstArmLink" />
    <child
      link="FLndArmLink" />
    <axis
      xyz="0 -1 0" />
    <safety_controller
      k_velocity="0" />
  </joint>
  <link
    name="RLndServoLink">
    <inertial>
      <origin
        xyz="0.0050221 0.0098017 -0.0019628"
        rpy="0 0 0" />
      <mass
        value="0.0089822" />
      <inertia
        ixx="3.7438E-07"
        ixy="4.1867E-10"
        ixz="1.3112E-07"
        iyy="5.0286E-07"
        iyz="-3.948E-11"
        izz="3.0506E-07" />
    </inertial>
    <visual>
      <origin
        xyz="0 0 0"
        rpy="0 0 0" />
      <geometry>
        <mesh
          filename="package://lizardv3_description/meshes/RLndServoLink.STL" />
      </geometry>
      <material
        name="">
        <color
          rgba="1 0.94902 0.9098 1" />
      </material>
    </visual>
    <collision>
      <origin
        xyz="0 0 0"
        rpy="0 0 0" />
      <geometry>
        <mesh
          filename="package://lizardv3_description/meshes/RLndServoLink.STL" />
      </geometry>
    </collision>
  </link>
  <joint
    name="RLndServoJnt"
    type="continuous">
    <origin
      xyz="0.00249999999999984 -0.00799999999999976 -0.016"
      rpy="0 0 -3.14159265358979" />
    <parent
      link="MainBoard" />
    <child
      link="RLndServoLink" />
    <axis
      xyz="0 -1 0" />
    <safety_controller
      k_velocity="0" />
  </joint>
  <link
    name="RLstArmLink">
    <inertial>
      <origin
        xyz="-0.0500875871726907 0.00194912579210623 0.000253934431699035"
        rpy="0 0 0" />
      <mass
        value="0.010727911839871" />
      <inertia
        ixx="4.12846705720797E-07"
        ixy="-3.43064372608672E-12"
        ixz="7.44939574750122E-12"
        iyy="1.46713624980483E-06"
        iyz="-9.74334437108359E-09"
        izz="1.1962482651381E-06" />
    </inertial>
    <visual>
      <origin
        xyz="0 0 0"
        rpy="0 0 0" />
      <geometry>
        <mesh
          filename="package://lizardv3_description/meshes/RLstArmLink.STL" />
      </geometry>
      <material
        name="">
        <color
          rgba="0.92156862745098 0.92156862745098 0.92156862745098 1" />
      </material>
    </visual>
    <collision>
      <origin
        xyz="0 0 0"
        rpy="0 0 0" />
      <geometry>
        <mesh
          filename="package://lizardv3_description/meshes/RLstArmLink.STL" />
      </geometry>
    </collision>
  </link>
  <joint
    name="RLstArmJnt"
    type="continuous">
    <origin
      xyz="0.0121985951706048 0.0116500000000019 0.0104316478019361"
      rpy="1.57079632679489 -0.872664625997154 3.14159265358979" />
    <parent
      link="RLndServoLink" />
    <child
      link="RLstArmLink" />
    <axis
      xyz="0 -1 0" />
    <safety_controller
      k_velocity="0" />
  </joint>
  <link
    name="RLndArmLink">
    <inertial>
      <origin
        xyz="-6.07153216591882E-16 0.00400000000000033 0.027108921736649"
        rpy="0 0 0" />
      <mass
        value="0.00368292036732051" />
      <inertia
        ixx="1.06068205884601E-06"
        ixy="-8.68539643180679E-24"
        ixz="-4.73767695839747E-22"
        iyy="1.0612743799609E-06"
        iyz="2.94088321938143E-21"
        izz="3.98768050329813E-08" />
    </inertial>
    <visual>
      <origin
        xyz="0 0 0"
        rpy="0 0 0" />
      <geometry>
        <mesh
          filename="package://lizardv3_description/meshes/RLndArmLink.STL" />
      </geometry>
      <material
        name="">
        <color
          rgba="0.92156862745098 0.92156862745098 0.92156862745098 1" />
      </material>
    </visual>
    <collision>
      <origin
        xyz="0 0 0"
        rpy="0 0 0" />
      <geometry>
        <mesh
          filename="package://lizardv3_description/meshes/RLndArmLink.STL" />
      </geometry>
    </collision>
  </link>
  <joint
    name="RLndArmJnt"
    type="continuous">
    <origin
      xyz="-0.0621 0.0150500000000294 0.00514999999999813"
      rpy="1.65099348915861 -1.57079631189374 -1.65101528723285" />
    <parent
      link="RLstArmLink" />
    <child
      link="RLndArmLink" />
    <axis
      xyz="0 -1 0" />
    <safety_controller
      k_velocity="0" />
  </joint>
  <link
    name="RRndServoLink">
    <inertial>
      <origin
        xyz="0.0050221 0.0098014 0.0019628"
        rpy="0 0 0" />
      <mass
        value="0.0089822" />
      <inertia
        ixx="3.7438E-07"
        ixy="4.0384E-10"
        ixz="-1.3112E-07"
        iyy="5.0286E-07"
        iyz="3.2482E-11"
        izz="3.0506E-07" />
    </inertial>
    <visual>
      <origin
        xyz="0 0 0"
        rpy="0 0 0" />
      <geometry>
        <mesh
          filename="package://lizardv3_description/meshes/RRndServoLink.STL" />
      </geometry>
      <material
        name="">
        <color
          rgba="0.74902 0.74902 0.74902 1" />
      </material>
    </visual>
    <collision>
      <origin
        xyz="0 0 0"
        rpy="0 0 0" />
      <geometry>
        <mesh
          filename="package://lizardv3_description/meshes/RRndServoLink.STL" />
      </geometry>
    </collision>
  </link>
  <joint
    name="RRndServoJnt"
    type="continuous">
    <origin
      xyz="0.0614999999999987 -0.00800000000000062 -0.0160000000000014"
      rpy="3.14159265358979 0 0" />
    <parent
      link="MainBoard" />
    <child
      link="RRndServoLink" />
    <axis
      xyz="0 -1 0" />
    <safety_controller
      k_velocity="0" />
  </joint>
  <link
    name="RRstArmLink">
    <inertial>
      <origin
        xyz="-0.050088 0.0019491 0.00025393"
        rpy="0 0 0" />
      <mass
        value="0.010728" />
      <inertia
        ixx="4.1285E-07"
        ixy="-3.4306E-12"
        ixz="7.4494E-12"
        iyy="1.4671E-06"
        iyz="-9.7433E-09"
        izz="1.1962E-06" />
    </inertial>
    <visual>
      <origin
        xyz="0 0 0"
        rpy="0 0 0" />
      <geometry>
        <mesh
          filename="package://lizardv3_description/meshes/RRstArmLink.STL" />
      </geometry>
      <material
        name="">
        <color
          rgba="0.92157 0.92157 0.92157 1" />
      </material>
    </visual>
    <collision>
      <origin
        xyz="0 0 0"
        rpy="0 0 0" />
      <geometry>
        <mesh
          filename="package://lizardv3_description/meshes/RRstArmLink.STL" />
      </geometry>
    </collision>
  </link>
  <joint
    name="RRstArmJnt"
    type="continuous">
    <origin
      xyz="0.0121985951706034 0.0116500000000019 -0.0104316478019393"
      rpy="-1.57079632679489 0.872664625997156 3.14159265358979" />
    <parent
      link="RRndServoLink" />
    <child
      link="RRstArmLink" />
    <axis
      xyz="0 -1 0" />
    <safety_controller
      k_velocity="0" />
  </joint>
  <link
    name="RRndArmLink">
    <inertial>
      <origin
        xyz="-2.77555756156289E-17 0.00400000000000003 0.0271089217366482"
        rpy="0 0 0" />
      <mass
        value="0.00368292036732051" />
      <inertia
        ixx="1.06068205884601E-06"
        ixy="-4.80798731046447E-24"
        ixz="1.0857149436542E-21"
        iyy="1.0612743799609E-06"
        iyz="-5.94009095143748E-22"
        izz="3.9876805032981E-08" />
    </inertial>
    <visual>
      <origin
        xyz="0 0 0"
        rpy="0 0 0" />
      <geometry>
        <mesh
          filename="package://lizardv3_description/meshes/RRndArmLink.STL" />
      </geometry>
      <material
        name="">
        <color
          rgba="0.92156862745098 0.92156862745098 0.92156862745098 1" />
      </material>
    </visual>
    <collision>
      <origin
        xyz="0 0 0"
        rpy="0 0 0" />
      <geometry>
        <mesh
          filename="package://lizardv3_description/meshes/RRndArmLink.STL" />
      </geometry>
    </collision>
  </link>
  <joint
    name="RRndArmJnt"
    type="continuous">
    <origin
      xyz="-0.0621 0.01505 0.00515"
      rpy="-1.3846 -1.5708 1.3846" />
    <parent
      link="RRstArmLink" />
    <child
      link="RRndArmLink" />
    <axis
      xyz="0 -1 0" />
    <safety_controller
      k_velocity="0" />
  </joint>
  <link
    name="HEADndServoLink">
    <inertial>
      <origin
        xyz="0.00817073701079046 -0.00971625046859658 0.00145467719884415"
        rpy="0 0 0" />
      <mass
        value="0.0121934443229411" />
      <inertia
        ixx="4.23955060797601E-07"
        ixy="-9.10853302793211E-08"
        ixz="-1.63814913779297E-08"
        iyy="1.21995274972379E-06"
        iyz="-8.11641325007153E-09"
        izz="1.31199137763511E-06" />
    </inertial>
    <visual>
      <origin
        xyz="0 0 0"
        rpy="0 0 0" />
      <geometry>
        <mesh
          filename="package://lizardv3_description/meshes/HEADndServoLink.STL" />
      </geometry>
      <material
        name="">
        <color
          rgba="0.749019607843137 0.749019607843137 0.749019607843137 1" />
      </material>
    </visual>
    <collision>
      <origin
        xyz="0 0 0"
        rpy="0 0 0" />
      <geometry>
        <mesh
          filename="package://lizardv3_description/meshes/HEADndServoLink.STL" />
      </geometry>
    </collision>
  </link>
  <joint
    name="HEADndServoJnt"
    type="continuous">
    <origin
      xyz="0.0319999999999842 0.108299999999999 0.0110499999999986"
      rpy="-1.5707963267949 0 -1.5707963267949" />
    <parent
      link="MainBoard" />
    <child
      link="HEADndServoLink" />
    <axis
      xyz="0 1 0" />
    <safety_controller
      k_velocity="0" />
  </joint>
  <link
    name="HEADstArmLink">
    <inertial>
      <origin
        xyz="-0.025127 0.013481 0.014507"
        rpy="0 0 0" />
      <mass
        value="0.0078839" />
      <inertia
        ixx="2.3678E-06"
        ixy="-8.5123E-08"
        ixz="1.304E-06"
        iyy="3.1243E-06"
        iyz="4.9146E-08"
        izz="3.8735E-06" />
    </inertial>
    <visual>
      <origin
        xyz="0 0 0"
        rpy="0 0 0" />
      <geometry>
        <mesh
          filename="package://lizardv3_description/meshes/HEADstArmLink.STL" />
      </geometry>
      <material
        name="">
        <color
          rgba="0.74902 0.74902 0.74902 1" />
      </material>
    </visual>
    <collision>
      <origin
        xyz="0 0 0"
        rpy="0 0 0" />
      <geometry>
        <mesh
          filename="package://lizardv3_description/meshes/HEADstArmLink.STL" />
      </geometry>
    </collision>
  </link>
  <joint
    name="HEADstArmJnt"
    type="continuous">
    <origin
      xyz="0.015 -0.0114 -0.01455"
      rpy="1.5708 0 0" />
    <parent
      link="HEADndServoLink" />
    <child
      link="HEADstArmLink" />
    <axis
      xyz="0 1 0" />
    <safety_controller
      k_velocity="0" />
  </joint>
  <link
    name="HEADLink">
    <inertial>
      <origin
        xyz="0.0554988766394613 0.00799999970901315 -0.00147454938363152"
        rpy="0 0 0" />
      <mass
        value="0.0177300364754162" />
      <inertia
        ixx="4.41581214683472E-06"
        ixy="-1.54454845134354E-12"
        ixz="2.20726693817977E-06"
        iyy="7.03739587968143E-06"
        iyz="4.16679611856128E-13"
        izz="8.27777171343773E-06" />
    </inertial>
    <visual>
      <origin
        xyz="0 0 0"
        rpy="0 0 0" />
      <geometry>
        <mesh
          filename="package://lizardv3_description/meshes/HEADLink.STL" />
      </geometry>
      <material
        name="">
        <color
          rgba="0.749019607843137 0.749019607843137 0.749019607843137 1" />
      </material>
    </visual>
    <collision>
      <origin
        xyz="0 0 0"
        rpy="0 0 0" />
      <geometry>
        <mesh
          filename="package://lizardv3_description/meshes/HEADLink.STL" />
      </geometry>
    </collision>
  </link>
  <joint
    name="HEADJnt"
    type="continuous">
    <origin
      xyz="-0.029976 0.0215 0.02308"
      rpy="0 -0.43294 -3.1416" />
    <parent
      link="HEADstArmLink" />
    <child
      link="HEADLink" />
    <axis
      xyz="0 1 0" />
    <safety_controller
      k_velocity="0" />
  </joint>
  <link
    name="HEADstArmParallelLink">
    <inertial>
      <origin
        xyz="-0.0122501451765017 0.00455000000000488 0.035245741804803"
        rpy="0 0 0" />
      <mass
        value="0.00373003311748238" />
      <inertia
        ixx="1.76654564691896E-06"
        ixy="1.02089597225529E-21"
        ixz="8.1677668885244E-07"
        iyy="1.9009569588329E-06"
        iyz="-1.64562412988596E-21"
        izz="8.23435633498772E-07" />
    </inertial>
    <visual>
      <origin
        xyz="0 0 0"
        rpy="0 0 0" />
      <geometry>
        <mesh
          filename="package://lizardv3_description/meshes/HEADstArmParallelLink.STL" />
      </geometry>
      <material
        name="">
        <color
          rgba="0.749019607843137 0.749019607843137 0.749019607843137 1" />
      </material>
    </visual>
    <collision>
      <origin
        xyz="0 0 0"
        rpy="0 0 0" />
      <geometry>
        <mesh
          filename="package://lizardv3_description/meshes/HEADstArmParallelLink.STL" />
      </geometry>
    </collision>
  </link>
  <joint
    name="HEADstArmParallelLJnt"
    type="continuous">
    <origin
      xyz="-0.0079 -0.0155 0.0035"
      rpy="-1.5708 0 1.5708" />
    <parent
      link="HEADndServoLink" />
    <child
      link="HEADstArmParallelLink" />
    <axis
      xyz="0 1 0" />
    <safety_controller
      k_velocity="0" />
  </joint>
  <link
    name="HEADParallelLink">
    <inertial>
      <origin
        xyz="-0.01342 -0.0002311 0.0126"
        rpy="0 0 0" />
      <mass
        value="0.01773" />
      <inertia
        ixx="7.8539E-06"
        ixy="2.5011E-06"
        ixz="-2.7193E-07"
        iyy="4.8653E-06"
        iyz="2.3576E-07"
        izz="7.0118E-06" />
    </inertial>
    <visual>
      <origin
        xyz="0 0 0"
        rpy="0 0 0" />
      <geometry>
        <mesh
          filename="package://lizardv3_description/meshes/HEADParallelLink.STL" />
      </geometry>
      <material
        name="">
        <color
          rgba="0.74902 0.74902 0.74902 1" />
      </material>
    </visual>
    <collision>
      <origin
        xyz="0 0 0"
        rpy="0 0 0" />
      <geometry>
        <mesh
          filename="package://lizardv3_description/meshes/HEADParallelLink.STL" />
      </geometry>
    </collision>
  </link>
  <joint
    name="HEADParallelJnt"
    type="continuous">
    <origin
      xyz="-0.0285 -0.00795 0.063391"
      rpy="-1.4626 -0.52244 0.00014562" />
    <parent
      link="HEADstArmParallelLink" />
    <child
      link="HEADParallelLink" />
    <axis
      xyz="0.0001262 0.10805 0.99415" />
    <safety_controller
      k_velocity="0" />
  </joint>
  <link
    name="TailndServoLink">
    <inertial>
      <origin
        xyz="-0.0048574 -0.016189 0.0010767"
        rpy="0 0 0" />
      <mass
        value="0.015139" />
      <inertia
        ixx="7.7721E-07"
        ixy="-7.035E-09"
        ixz="1.3267E-08"
        iyy="1.4848E-06"
        iyz="3.8044E-08"
        izz="1.876E-06" />
    </inertial>
    <visual>
      <origin
        xyz="0 0 0"
        rpy="0 0 0" />
      <geometry>
        <mesh
          filename="package://lizardv3_description/meshes/TailndServoLink.STL" />
      </geometry>
      <material
        name="">
        <color
          rgba="0.74902 0.74902 0.74902 1" />
      </material>
    </visual>
    <collision>
      <origin
        xyz="0 0 0"
        rpy="0 0 0" />
      <geometry>
        <mesh
          filename="package://lizardv3_description/meshes/TailndServoLink.STL" />
      </geometry>
    </collision>
  </link>
  <joint
    name="TailndServoJnt"
    type="continuous">
    <origin
      xyz="0.032 -0.02925 -0.02105"
      rpy="1.5708 0 -1.5708" />
    <parent
      link="MainBoard" />
    <child
      link="TailndServoLink" />
    <axis
      xyz="0 1 0" />
    <safety_controller
      k_velocity="0" />
  </joint>
  <link
    name="TAILstArmLink">
    <inertial>
      <origin
        xyz="0.0054385 0.018255 0.042426"
        rpy="0 0 0" />
      <mass
        value="0.013285" />
      <inertia
        ixx="1.5067E-05"
        ixy="-1.6352E-10"
        ixz="1.9782E-07"
        iyy="1.9317E-05"
        iyz="1.2276E-08"
        izz="4.4632E-06" />
    </inertial>
    <visual>
      <origin
        xyz="0 0 0"
        rpy="0 0 0" />
      <geometry>
        <mesh
          filename="package://lizardv3_description/meshes/TAILstArmLink.STL" />
      </geometry>
      <material
        name="">
        <color
          rgba="0.92157 0.92157 0.92157 1" />
      </material>
    </visual>
    <collision>
      <origin
        xyz="0 0 0"
        rpy="0 0 0" />
      <geometry>
        <mesh
          filename="package://lizardv3_description/meshes/TAILstArmLink.STL" />
      </geometry>
    </collision>
  </link>
  <joint
    name="TAILstArmJnt"
    type="continuous">
    <origin
      xyz="0.01235 -0.002 -0.00545"
      rpy="1.019 -1.5708 2.1225" />
    <parent
      link="TailndServoLink" />
    <child
      link="TAILstArmLink" />
    <axis
      xyz="1 0 0" />
    <safety_controller
      k_velocity="0" />
  </joint>
  <link
    name="TAILLink">
    <inertial>
      <origin
        xyz="0.0693819489154556 0.00236468450873411 0.0174996318739005"
        rpy="0 0 0" />
      <mass
        value="0.0170255571844121" />
      <inertia
        ixx="1.10748675129764E-06"
        ixy="5.92827428438699E-07"
        ixz="2.68673058943583E-10"
        iyy="9.48088608953699E-06"
        iyz="-2.33873685029435E-12"
        izz="9.05157957329576E-06" />
    </inertial>
    <visual>
      <origin
        xyz="0 0 0"
        rpy="0 0 0" />
      <geometry>
        <mesh
          filename="package://lizardv3_description/meshes/TAILLink.STL" />
      </geometry>
      <material
        name="">
        <color
          rgba="0.749019607843137 0.749019607843137 0.749019607843137 1" />
      </material>
    </visual>
    <collision>
      <origin
        xyz="0 0 0"
        rpy="0 0 0" />
      <geometry>
        <mesh
          filename="package://lizardv3_description/meshes/TAILLink.STL" />
      </geometry>
    </collision>
  </link>
  <joint
    name="TAILJnt"
    type="continuous">
    <origin
      xyz="-0.01205 0.018236 0.06515"
      rpy="-1.5708 -1.57 -1.5708" />
    <parent
      link="TAILstArmLink" />
    <child
      link="TAILLink" />
    <axis
      xyz="0 0 1" />
    <safety_controller
      k_velocity="0" />
  </joint>
  <link
    name="TAILstArmParallelLink">
    <inertial>
      <origin
        xyz="0.00570000000000003 -0.04815 0.00754999999999956"
        rpy="0 0 0" />
      <mass
        value="0.0110994579255875" />
      <inertia
        ixx="1.38627444069151E-05"
        ixy="2.62740275207101E-21"
        ixz="-4.75659441497189E-22"
        iyy="1.63407638509854E-06"
        iyz="-3.12746649848643E-21"
        izz="1.23476561550545E-05" />
    </inertial>
    <visual>
      <origin
        xyz="0 0 0"
        rpy="0 0 0" />
      <geometry>
        <mesh
          filename="package://lizardv3_description/meshes/TAILstArmParallelLink.STL" />
      </geometry>
      <material
        name="">
        <color
          rgba="0.749019607843137 0.749019607843137 0.749019607843137 1" />
      </material>
    </visual>
    <collision>
      <origin
        xyz="0 0 0"
        rpy="0 0 0" />
      <geometry>
        <mesh
          filename="package://lizardv3_description/meshes/TAILstArmParallelLink.STL" />
      </geometry>
    </collision>
  </link>
  <joint
    name="TAILstArmParallelJnt"
    type="continuous">
    <origin
      xyz="0.01235 -0.002 0.00755"
      rpy="-3.1416 0 -1.5708" />
    <parent
      link="TailndServoLink" />
    <child
      link="TAILstArmParallelLink" />
    <axis
      xyz="0 0 -1" />
    <safety_controller
      k_velocity="0" />
  </joint>
  <link
    name="TAILParallelLink">
    <inertial>
      <origin
        xyz="0.0638799444695541 -0.0101139262583112 0.00999963187390017"
        rpy="0 0 0" />
      <mass
        value="0.0170255571844121" />
      <inertia
        ixx="1.10651259072902E-06"
        ixy="5.85906456236652E-07"
        ixz="2.68674900034565E-10"
        iyy="9.48186025010561E-06"
        iyz="-2.11669219327405E-12"
        izz="9.05157957329576E-06" />
    </inertial>
    <visual>
      <origin
        xyz="0 0 0"
        rpy="0 0 0" />
      <geometry>
        <mesh
          filename="package://lizardv3_description/meshes/TAILParallelLink.STL" />
      </geometry>
      <material
        name="">
        <color
          rgba="0.749019607843137 0.749019607843137 0.749019607843137 1" />
      </material>
    </visual>
    <collision>
      <origin
        xyz="0 0 0"
        rpy="0 0 0" />
      <geometry>
        <mesh
          filename="package://lizardv3_description/meshes/TAILParallelLink.STL" />
      </geometry>
    </collision>
  </link>
  <joint
    name="TAILParallelJnt"
    type="continuous">
    <origin
      xyz="0.0057 -0.07065 0.01755"
      rpy="-3.1416 0 -1.5708" />
    <parent
      link="TAILstArmParallelLink" />
    <child
      link="TAILParallelLink" />
    <axis
      xyz="0 0 1" />
    <safety_controller
      k_velocity="0" />
  </joint>

  <!-- ################### TRANSMISSION Definitions ############################# -->
  <!-- ################### TRANSMISSION Definitions ############################# -->

  <!-- front right leg -->
  <transmission name="transmission_front_right_leg_1">
    <type>transmission_interface/SimpleTransmission</type>
    <actuator name="servo_front_right_leg_1">
      <mechanicalReduction>1</mechanicalReduction>
      <hardwareInterface>hardware_interface/EffortJointInterface</hardwareInterface>
    </actuator>
    <joint name="FRndServoJnt">
      <hardwareInterface>hardware_interface/EffortJointInterface</hardwareInterface>
    </joint>
  </transmission>

  <transmission name="transmission_front_right_leg_2">
    <type>transmission_interface/SimpleTransmission</type>
    <actuator name="servo_front_right_leg_2">
      <mechanicalReduction>1</mechanicalReduction>
      <hardwareInterface>hardware_interface/EffortJointInterface</hardwareInterface>
    </actuator>
    <joint name="FRstArmJnt">
      <hardwareInterface>hardware_interface/EffortJointInterface</hardwareInterface>
    </joint>
  </transmission>

  <transmission name="transmission_front_right_leg_3">
    <type>transmission_interface/SimpleTransmission</type>
    <actuator name="servo_front_right_leg_3">
      <mechanicalReduction>1</mechanicalReduction>
      <hardwareInterface>hardware_interface/EffortJointInterface</hardwareInterface>
    </actuator>
    <joint name="FRndArmJnt">
      <hardwareInterface>hardware_interface/EffortJointInterface</hardwareInterface>
    </joint>
  </transmission>

  <!-- front left leg -->
  <transmission name="transmission_front_left_leg_1">
    <type>transmission_interface/SimpleTransmission</type>
    <actuator name="servo_front_left_leg_1">
      <mechanicalReduction>1</mechanicalReduction>
      <hardwareInterface>hardware_interface/EffortJointInterface</hardwareInterface>
    </actuator>
    <joint name="FLndServoJnt">
      <hardwareInterface>hardware_interface/EffortJointInterface</hardwareInterface>
    </joint>
  </transmission>

  <transmission name="transmission_front_left_leg_2">
    <type>transmission_interface/SimpleTransmission</type>
    <actuator name="servo_front_left_leg_2">
      <mechanicalReduction>1</mechanicalReduction>
      <hardwareInterface>hardware_interface/EffortJointInterface</hardwareInterface>
    </actuator>
    <joint name="FLstArmJnt">
      <hardwareInterface>hardware_interface/EffortJointInterface</hardwareInterface>
    </joint>
  </transmission>

  <transmission name="transmission_front_left_leg_3">
    <type>transmission_interface/SimpleTransmission</type>
    <actuator name="servo_front_left_leg_3">
      <mechanicalReduction>1</mechanicalReduction>
      <hardwareInterface>hardware_interface/EffortJointInterface</hardwareInterface>
    </actuator>
    <joint name="FLndArmJnt">
      <hardwareInterface>hardware_interface/EffortJointInterface</hardwareInterface>
    </joint>
  </transmission>

  <!-- rear right leg -->
  <transmission name="transmission_rear_right_leg_1">
    <type>transmission_interface/SimpleTransmission</type>
    <actuator name="servo_rear_right_leg_1">
      <mechanicalReduction>1</mechanicalReduction>
      <hardwareInterface>hardware_interface/EffortJointInterface</hardwareInterface>
    </actuator>
    <joint name="RRndServoJnt">
      <hardwareInterface>hardware_interface/EffortJointInterface</hardwareInterface>
    </joint>
  </transmission>

  <transmission name="transmission_rear_right_leg_2">
    <type>transmission_interface/SimpleTransmission</type>
    <actuator name="servo_rear_right_leg_2">
      <mechanicalReduction>1</mechanicalReduction>
      <hardwareInterface>hardware_interface/EffortJointInterface</hardwareInterface>
    </actuator>
    <joint name="RRstArmJnt">
      <hardwareInterface>hardware_interface/EffortJointInterface</hardwareInterface>
    </joint>
  </transmission>

  <transmission name="transmission_rear_right_leg_3">
    <type>transmission_interface/SimpleTransmission</type>
    <actuator name="servo_rear_right_leg_3">
      <mechanicalReduction>1</mechanicalReduction>
      <hardwareInterface>hardware_interface/EffortJointInterface</hardwareInterface>
    </actuator>
    <joint name="RRndArmJnt">
      <hardwareInterface>hardware_interface/EffortJointInterface</hardwareInterface>
    </joint>
  </transmission>

  <!-- rear left leg -->
  <transmission name="transmission_rear_left_leg_1">
    <type>transmission_interface/SimpleTransmission</type>
    <actuator name="servo_rear_left_leg_1">
      <mechanicalReduction>1</mechanicalReduction>
      <hardwareInterface>hardware_interface/EffortJointInterface</hardwareInterface>
    </actuator>
    <joint name="RLndServoJnt">
      <hardwareInterface>hardware_interface/EffortJointInterface</hardwareInterface>
    </joint>
  </transmission>

  <transmission name="transmission_rear_left_leg_2">
    <type>transmission_interface/SimpleTransmission</type>
    <actuator name="servo_rear_left_leg_2">
      <mechanicalReduction>1</mechanicalReduction>
      <hardwareInterface>hardware_interface/EffortJointInterface</hardwareInterface>
    </actuator>
    <joint name="RLstArmJnt">
      <hardwareInterface>hardware_interface/EffortJointInterface</hardwareInterface>
    </joint>
  </transmission>

  <transmission name="transmission_rear_left_leg_3">
    <type>transmission_interface/SimpleTransmission</type>
    <actuator name="servo_rear_left_leg_3">
      <mechanicalReduction>1</mechanicalReduction>
      <hardwareInterface>hardware_interface/EffortJointInterface</hardwareInterface>
    </actuator>
    <joint name="RLndArmJnt">
      <hardwareInterface>hardware_interface/EffortJointInterface</hardwareInterface>
    </joint>
  </transmission>

  <!-- ################### MATERIALS Definitions ############################# -->
  <!-- ################### MATERIALS Definitions ############################# -->

  <!-- ################### SENSOR Definitions ############################# -->
  <!-- ################### SENSOR Definitions ############################# -->

  <gazebo>
    <plugin filename="libgazebo_ros_imu.so" name="gazebo_ros_imu_controller">
      <robotNamespace>/barabasz</robotNamespace>
      <topicName>imu/data</topicName>
      <serviceName>imu/service</serviceName>
      <bodyName>MainBoard</bodyName>
      <gaussianNoise>0</gaussianNoise>
      <rpyOffsets>0 0 0</rpyOffsets>
      <updateRate>10.0</updateRate>
      <alwaysOn>true</alwaysOn>
      <gaussianNoise>0</gaussianNoise>
    </plugin>
  </gazebo>


  <!-- ################### GAZEBO PLUGINS Definitions ############################# -->
  <!-- ################### GAZEBO PLUGINS Definitions ############################# -->

  <gazebo>
      <plugin filename="libgazebo_ros_control.so" name="gazebo_ros_control">
        <robotNamespace>/barabasz</robotNamespace>
      </plugin>
  </gazebo>
</robot>
