<?xml version="1.0" encoding="utf-8"?>
<!-- This URDF was automatically created by SolidWorks to URDF Exporter! Originally created by Stephen Brawner (brawner@gmail.com) 
     Commit Version: 1.5.0-0-g9aa0fdb  Build Version: 1.5.7004.21443
     For more information, please see http://wiki.ros.org/sw_urdf_exporter -->
<robot
  name="lizard_description">
  <link
    name="belly">
    <inertial>
      <origin
        xyz="0.03 0.045 0.0086392"
        rpy="0 0 0" />
      <mass
        value="0.12561" />
      <inertia
        ixx="0.00019491"
        ixy="1.0522E-20"
        ixz="9.9374E-22"
        iyy="6.826E-05"
        iyz="-3.2518E-22"
        izz="0.00025927" />
    </inertial>
    <visual>
      <origin
        xyz="0 0 0"
        rpy="0 0 0" />
      <geometry>
        <mesh
          filename="package://lizard_description/meshes/belly.STL" />
      </geometry>
      <material
        name="">
        <color
          rgba="0.91765 0.91765 0.91765 1" />
      </material>
    </visual>
    <collision>
      <origin
        xyz="0 0 0"
        rpy="0 0 0" />
      <geometry>
        <mesh
          filename="package://lizard_description/meshes/belly.STL" />
      </geometry>
    </collision>
  </link>
  <link
    name="FRstServoLink">
    <inertial>
      <origin
        xyz="0.00982301146692348 0.0100133157576773 0.00609982243576659"
        rpy="0 0 0" />
      <mass
        value="0.00746769202007824" />
      <inertia
        ixx="4.30213630580842E-07"
        ixy="-1.03279472389634E-08"
        ixz="3.63105904300421E-12"
        iyy="1.43700202219469E-07"
        iyz="-7.8895640909465E-12"
        izz="3.95348133595681E-07" />
    </inertial>
    <visual>
      <origin
        xyz="0 0 0"
        rpy="0 0 0" />
      <geometry>
        <mesh
          filename="package://lizard_description/meshes/FRstServoLink.STL" />
      </geometry>
      <material
        name="">
        <color
          rgba="1 0.949019607843137 0.909803921568627 1" />
      </material>
    </visual>
    <collision>
      <origin
        xyz="0 0 0"
        rpy="0 0 0" />
      <geometry>
        <mesh
          filename="package://lizard_description/meshes/FRstServoLink.STL" />
      </geometry>
    </collision>
  </link>
  <joint
    name="FRstServoJnt"
    type="fixed">
    <origin
      xyz="0.07 -0.01 0.015"
      rpy="0 0 1.5708" />
    <parent
      link="belly" />
    <child
      link="FRstServoLink" />
    <axis
      xyz="0 0 0" />
    <safety_controller
      k_velocity="0" />
  </joint>
  <link
    name="FRplateLink">
    <inertial>
      <origin
        xyz="0.00668019140904452 0.00393393093402902 0.00614981938219049"
        rpy="0 0 0" />
      <mass
        value="0.0019371681469282" />
      <inertia
        ixx="1.2989349389867E-07"
        ixy="2.22458553397162E-10"
        ixz="3.47764093056011E-10"
        iyy="6.83273335716312E-08"
        iyz="1.47233380560847E-09"
        izz="6.96871715585702E-08" />
    </inertial>
    <visual>
      <origin
        xyz="0 0 0"
        rpy="0 0 0" />
      <geometry>
        <mesh
          filename="package://lizard_description/meshes/FRplateLink.STL" />
      </geometry>
      <material
        name="">
        <color
          rgba="0.749019607843137 0.749019607843137 0.749019607843137 1" />
      </material>
    </visual>
    <collision>
      <origin
        xyz="0 0 0"
        rpy="0 0 0" />
      <geometry>
        <mesh
          filename="package://lizard_description/meshes/FRplateLink.STL" />
      </geometry>
    </collision>
  </link>
  <joint
    name="FRplateJnt"
    type="continuous">
    <origin
      xyz="-9.9E-05 0.00525 0.0061"
      rpy="-0.7854 0 -3.1416" />
    <parent
      link="FRstServoLink" />
    <child
      link="FRplateLink" />
    <axis
      xyz="1 0 0" />
    <safety_controller
      k_velocity="0" />
  </joint>
  <link
    name="FRndServoLink">
    <inertial>
      <origin
        xyz="0.0168769876393255 0.0103866842603198 0.00609982230844828"
        rpy="0 0 0" />
      <mass
        value="0.00746769221167402" />
      <inertia
        ixx="4.30213662397098E-07"
        ixy="-1.03279128219074E-08"
        ixz="-3.63142581155928E-12"
        iyy="1.43700191865541E-07"
        iyz="7.87859191332848E-12"
        izz="3.95348121118197E-07" />
    </inertial>
    <visual>
      <origin
        xyz="0 0 0"
        rpy="0 0 0" />
      <geometry>
        <mesh
          filename="package://lizard_description/meshes/FRndServoLink.STL" />
      </geometry>
      <material
        name="">
        <color
          rgba="1 0.949019607843137 0.909803921568627 1" />
      </material>
    </visual>
    <collision>
      <origin
        xyz="0 0 0"
        rpy="0 0 0" />
      <geometry>
        <mesh
          filename="package://lizard_description/meshes/FRndServoLink.STL" />
      </geometry>
    </collision>
  </link>
  <joint
    name="FRndServoJnt"
    type="fixed">
    <origin
      xyz="0.009151 -0.0038103 -0.0059566"
      rpy="1.5708 -0.21631 1.5708" />
    <parent
      link="FRplateLink" />
    <child
      link="FRndServoLink" />
    <axis
      xyz="0 0 0" />
    <safety_controller
      k_velocity="0" />
  </joint>
  <link
    name="FRstArmLink">
    <inertial>
      <origin
        xyz="-0.0269507106222497 0.00410000000000087 -0.00292452298323934"
        rpy="0 0 0" />
      <mass
        value="0.00390389558935974" />
      <inertia
        ixx="5.48625626225724E-08"
        ixy="4.09834906295523E-20"
        ixz="-1.16051172864203E-07"
        iyy="1.12495084275856E-06"
        iyz="4.44077624602567E-21"
        izz="1.11172983308916E-06" />
    </inertial>
    <visual>
      <origin
        xyz="0 0 0"
        rpy="0 0 0" />
      <geometry>
        <mesh
          filename="package://lizard_description/meshes/FRstArmLink.STL" />
      </geometry>
      <material
        name="">
        <color
          rgba="0.917647058823529 0.917647058823529 0.917647058823529 1" />
      </material>
    </visual>
    <collision>
      <origin
        xyz="0 0 0"
        rpy="0 0 0" />
      <geometry>
        <mesh
          filename="package://lizard_description/meshes/FRstArmLink.STL" />
      </geometry>
    </collision>
  </link>
  <joint
    name="FRstArmJnt"
    type="continuous">
    <origin
      xyz="0.03095 0.01515 0.0061"
      rpy="0 0 -1.5708" />
    <parent
      link="FRndServoLink" />
    <child
      link="FRstArmLink" />
    <axis
      xyz="0 1 0" />
    <safety_controller
      k_velocity="0" />
  </joint>
  <link
    name="FRrdServoLink">
    <inertial>
      <origin
        xyz="0.00260017760807482 0.00463668422140362 0.0125769882228761"
        rpy="0 0 0" />
      <mass
        value="0.00746769199220507" />
      <inertia
        ixx="3.95348127647139E-07"
        ixy="-7.88706847151875E-12"
        ixz="3.63087709548236E-12"
        iyy="1.43700197181375E-07"
        iyz="-1.0327938443167E-08"
        izz="4.3021363700595E-07" />
    </inertial>
    <visual>
      <origin
        xyz="0 0 0"
        rpy="0 0 0" />
      <geometry>
        <mesh
          filename="package://lizard_description/meshes/FRrdServoLink.STL" />
      </geometry>
      <material
        name="">
        <color
          rgba="1 0.949019607843137 0.909803921568627 1" />
      </material>
    </visual>
    <collision>
      <origin
        xyz="0 0 0"
        rpy="0 0 0" />
      <geometry>
        <mesh
          filename="package://lizard_description/meshes/FRrdServoLink.STL" />
      </geometry>
    </collision>
  </link>
  <joint
    name="FRrdServoJnt"
    type="fixed">
    <origin
      xyz="-0.055242 0.0081 -0.010018"
      rpy="1.6789 0 -1.5708" />
    <parent
      link="FRstArmLink" />
    <child
      link="FRrdServoLink" />
    <axis
      xyz="0 0 0" />
    <safety_controller
      k_velocity="0" />
  </joint>
  <link
    name="FRndArmLink">
    <inertial>
      <origin
        xyz="0.00825000000000063 -0.0194715580023163 -0.0188613909000947"
        rpy="0 0 0" />
      <mass
        value="0.00390389558935974" />
      <inertia
        ixx="1.12495084275856E-06"
        ixy="2.28963593554678E-20"
        ixz="2.21022659674169E-20"
        iyy="5.66076905592061E-07"
        iyz="-5.40752695363567E-07"
        izz="6.00515490119668E-07" />
    </inertial>
    <visual>
      <origin
        xyz="0 0 0"
        rpy="0 0 0" />
      <geometry>
        <mesh
          filename="package://lizard_description/meshes/FRndArmLink.STL" />
      </geometry>
      <material
        name="">
        <color
          rgba="0.917647058823529 0.917647058823529 0.917647058823529 1" />
      </material>
    </visual>
    <collision>
      <origin
        xyz="0 0 0"
        rpy="0 0 0" />
      <geometry>
        <mesh
          filename="package://lizard_description/meshes/FRndArmLink.STL" />
      </geometry>
    </collision>
  </link>
  <joint
    name="FRndArmJnt"
    type="continuous">
    <origin
      xyz="0.0026 0.0094 0.0225"
      rpy="0.90142 -1.5708 0" />
    <parent
      link="FRrdServoLink" />
    <child
      link="FRndArmLink" />
    <axis
      xyz="-1 0 0" />
    <safety_controller
      k_velocity="0" />
  </joint>
  <link
    name="FLstServoLink">
    <inertial>
      <origin
        xyz="0.0100133157573078 0.0098230114666415 0.00610017756399171"
        rpy="0 0 0" />
      <mass
        value="0.00746769202030283" />
      <inertia
        ixx="1.4370020221647E-07"
        ixy="-1.03279472451323E-08"
        ixz="7.88955387781639E-12"
        iyy="4.30213630601606E-07"
        iyz="-3.63106347865435E-12"
        izz="3.9534813362142E-07" />
    </inertial>
    <visual>
      <origin
        xyz="0 0 0"
        rpy="0 0 0" />
      <geometry>
        <mesh
          filename="package://lizard_description/meshes/FLstServoLink.STL" />
      </geometry>
      <material
        name="">
        <color
          rgba="1 0.949019607843137 0.909803921568627 1" />
      </material>
    </visual>
    <collision>
      <origin
        xyz="0 0 0"
        rpy="0 0 0" />
      <geometry>
        <mesh
          filename="package://lizard_description/meshes/FLstServoLink.STL" />
      </geometry>
    </collision>
  </link>
  <joint
    name="FLstSevoJnt"
    type="fixed">
    <origin
      xyz="-0.01 -0.01 0.015"
      rpy="0 0 0" />
    <parent
      link="belly" />
    <child
      link="FLstServoLink" />
    <axis
      xyz="0 0 0" />
    <safety_controller
      k_velocity="0" />
  </joint>
  <link
    name="FLplateLink">
    <inertial>
      <origin
        xyz="0.00700458579898856 0.00252919140904428 -0.00205715065366482"
        rpy="0 0 0" />
      <mass
        value="0.00193716814692821" />
      <inertia
        ixx="7.0371454726811E-08"
        ixy="3.960999951759E-10"
        ixz="-8.76931659140639E-10"
        iyy="1.2989349389867E-07"
        iyz="-1.16329128855733E-10"
        izz="6.76430504033906E-08" />
    </inertial>
    <visual>
      <origin
        xyz="0 0 0"
        rpy="0 0 0" />
      <geometry>
        <mesh
          filename="package://lizard_description/meshes/FLplateLink.STL" />
      </geometry>
      <material
        name="">
        <color
          rgba="0.749019607843137 0.749019607843137 0.749019607843137 1" />
      </material>
    </visual>
    <collision>
      <origin
        xyz="0 0 0"
        rpy="0 0 0" />
      <geometry>
        <mesh
          filename="package://lizard_description/meshes/FLplateLink.STL" />
      </geometry>
    </collision>
  </link>
  <joint
    name="FLplateJnt"
    type="continuous">
    <origin
      xyz="0.00525 -0.00425 0.0061"
      rpy="0 0 -3.1416" />
    <parent
      link="FLstServoLink" />
    <child
      link="FLplateLink" />
    <axis
      xyz="0 1 0" />
    <safety_controller
      k_velocity="0" />
  </joint>
  <link
    name="FLndServoLink">
    <inertial>
      <origin
        xyz="0.00961331556405451 0.0124769884120718 -0.00610017785206844"
        rpy="0 0 0" />
      <mass
        value="0.0074676934157608" />
      <inertia
        ixx="1.43700195463786E-07"
        ixy="1.03279015438127E-08"
        ixz="-7.87721700254369E-12"
        iyy="4.30213694151839E-07"
        iyz="-3.63085349524111E-12"
        izz="3.95348138553585E-07" />
    </inertial>
    <visual>
      <origin
        xyz="0 0 0"
        rpy="0 0 0" />
      <geometry>
        <mesh
          filename="package://lizard_description/meshes/FLndServoLink.STL" />
      </geometry>
      <material
        name="">
        <color
          rgba="1 0.949019607843137 0.909803921568627 1" />
      </material>
    </visual>
    <collision>
      <origin
        xyz="0 0 0"
        rpy="0 0 0" />
      <geometry>
        <mesh
          filename="package://lizard_description/meshes/FLndServoLink.STL" />
      </geometry>
    </collision>
  </link>
  <joint
    name="FLndServoJnt"
    type="fixed">
    <origin
      xyz="0.012878 0.005 0.0077146"
      rpy="-1.5708 0.49974 3.1416" />
    <parent
      link="FLplateLink" />
    <child
      link="FLndServoLink" />
    <axis
      xyz="0 0 0" />
    <safety_controller
      k_velocity="0" />
  </joint>
  <link
    name="FLstArmLink">
    <inertial>
      <origin
        xyz="0.00825000000000001 -0.0271079361760165 0.000231157956261309"
        rpy="0 0 0" />
      <mass
        value="0.00390389558935974" />
      <inertia
        ixx="1.12495084275856E-06"
        ixy="1.75362289861242E-21"
        ixz="-4.07948265128109E-23"
        iyy="4.23480892796739E-08"
        iyz="9.22634255113664E-09"
        izz="1.12424430643205E-06" />
    </inertial>
    <visual>
      <origin
        xyz="0 0 0"
        rpy="0 0 0" />
      <geometry>
        <mesh
          filename="package://lizard_description/meshes/FLstArmLink.STL" />
      </geometry>
      <material
        name="">
        <color
          rgba="0.917647058823529 0.917647058823529 0.917647058823529 1" />
      </material>
    </visual>
    <collision>
      <origin
        xyz="0 0 0"
        rpy="0 0 0" />
      <geometry>
        <mesh
          filename="package://lizard_description/meshes/FLstArmLink.STL" />
      </geometry>
    </collision>
  </link>
  <joint
    name="FLstArmJnt"
    type="continuous">
    <origin
      xyz="0.00485 0.0224 -0.0061"
      rpy="3.1416 0 1.5708" />
    <parent
      link="FLndServoLink" />
    <child
      link="FLstArmLink" />
    <axis
      xyz="-1 0 0" />
    <safety_controller
      k_velocity="0" />
  </joint>
  <link
    name="FLrdServoLink">
    <inertial>
      <origin
        xyz="0.00399982242724478 0.00438668425194329 -0.0125769885522945"
        rpy="0 0 0" />
      <mass
        value="0.00746769206909512" />
      <inertia
        ixx="3.95348133617446E-07"
        ixy="7.88921034835249E-12"
        ixz="3.63101112382171E-12"
        iyy="1.43700201560523E-07"
        iyz="1.03279459294475E-08"
        izz="4.30213632719249E-07" />
    </inertial>
    <visual>
      <origin
        xyz="0 0 0"
        rpy="0 0 0" />
      <geometry>
        <mesh
          filename="package://lizard_description/meshes/FLrdServoLink.STL" />
      </geometry>
      <material
        name="">
        <color
          rgba="1 0.949019607843137 0.909803921568627 1" />
      </material>
    </visual>
    <collision>
      <origin
        xyz="0 0 0"
        rpy="0 0 0" />
      <geometry>
        <mesh
          filename="package://lizard_description/meshes/FLrdServoLink.STL" />
      </geometry>
    </collision>
  </link>
  <joint
    name="FLrdServoJnt"
    type="fixed">
    <origin
      xyz="0.01225 -0.056032 -0.0035223"
      rpy="1.5793 0 -3.1416" />
    <parent
      link="FLstArmLink" />
    <child
      link="FLrdServoLink" />
    <axis
      xyz="0 0 0" />
    <safety_controller
      k_velocity="0" />
  </joint>
  <link
    name="FLndArmLink">
    <inertial>
      <origin
        xyz="-0.0271089217366485 0.00825000000000112 -2.4980018054066E-16"
        rpy="0 0 0" />
      <mass
        value="0.00390389558935974" />
      <inertia
        ixx="4.226941333496E-08"
        ixy="2.64299973841119E-20"
        ixz="-4.31025722625483E-22"
        iyy="1.12495084275856E-06"
        iyz="1.05879118406788E-22"
        izz="1.12432298237677E-06" />
    </inertial>
    <visual>
      <origin
        xyz="0 0 0"
        rpy="0 0 0" />
      <geometry>
        <mesh
          filename="package://lizard_description/meshes/FLndArmLink.STL" />
      </geometry>
      <material
        name="">
        <color
          rgba="0.917647058823529 0.917647058823529 0.917647058823529 1" />
      </material>
    </visual>
    <collision>
      <origin
        xyz="0 0 0"
        rpy="0 0 0" />
      <geometry>
        <mesh
          filename="package://lizard_description/meshes/FLndArmLink.STL" />
      </geometry>
    </collision>
  </link>
  <joint
    name="FLndArmJnt"
    type="continuous">
    <origin
      xyz="0.004 0.00915 -0.0225"
      rpy="-1.5708 0 -1.5708" />
    <parent
      link="FLrdServoLink" />
    <child
      link="FLndArmLink" />
    <axis
      xyz="0 -1 0" />
    <safety_controller
      k_velocity="0" />
  </joint>
  <link
    name="RRstServoLink">
    <inertial>
      <origin
        xyz="0.0100133157575187 0.00982301146658547 0.00610017756400114"
        rpy="0 0 0" />
      <mass
        value="0.00746769202033973" />
      <inertia
        ixx="1.43700202226749E-07"
        ixy="-1.032794724163E-08"
        ixz="7.88956138521972E-12"
        iyy="4.302136305912E-07"
        iyz="-3.63106326494752E-12"
        izz="3.95348133601827E-07" />
    </inertial>
    <visual>
      <origin
        xyz="0 0 0"
        rpy="0 0 0" />
      <geometry>
        <mesh
          filename="package://lizard_description/meshes/RRstServoLink.STL" />
      </geometry>
      <material
        name="">
        <color
          rgba="1 0.949019607843137 0.909803921568627 1" />
      </material>
    </visual>
    <collision>
      <origin
        xyz="0 0 0"
        rpy="0 0 0" />
      <geometry>
        <mesh
          filename="package://lizard_description/meshes/RRstServoLink.STL" />
      </geometry>
    </collision>
  </link>
  <joint
    name="RRstServoJnt"
    type="fixed">
    <origin
      xyz="0.07 0.1 0.015"
      rpy="0 0 3.1416" />
    <parent
      link="belly" />
    <child
      link="RRstServoLink" />
    <axis
      xyz="0 0 0" />
    <safety_controller
      k_velocity="0" />
  </joint>
  <link
    name="RRplateLink">
    <inertial>
      <origin
        xyz="0.00676495121694468 -0.00716406818044035 0.000905124877732241"
        rpy="0 0 0" />
      <mass
        value="0.0019371681469282" />
      <inertia
        ixx="1.2989484089839E-07"
        ixy="2.96495662438881E-10"
        ixz="5.59300435513508E-11"
        iyy="7.05777925877868E-08"
        iyz="-3.98396101087842E-10"
        izz="6.74353655426951E-08" />
    </inertial>
    <visual>
      <origin
        xyz="0 0 0"
        rpy="0 0 0" />
      <geometry>
        <mesh
          filename="package://lizard_description/meshes/RRplateLink.STL" />
      </geometry>
      <material
        name="">
        <color
          rgba="0.749019607843137 0.749019607843137 0.749019607843137 1" />
      </material>
    </visual>
    <collision>
      <origin
        xyz="0 0 0"
        rpy="0 0 0" />
      <geometry>
        <mesh
          filename="package://lizard_description/meshes/RRplateLink.STL" />
      </geometry>
    </collision>
  </link>
  <joint
    name="RRplateJnt"
    type="continuous">
    <origin
      xyz="0.00525 -0.0001 0.0061"
      rpy="0 0 -1.5827" />
    <parent
      link="RRstServoLink" />
    <child
      link="RRplateLink" />
    <axis
      xyz="0.99993 0.011904 0" />
    <safety_controller
      k_velocity="0" />
  </joint>
  <link
    name="RRndServoLink">
    <inertial>
      <origin
        xyz="0.00961331577515898 0.0168769874997621 -0.00610017780272777"
        rpy="0 0 0" />
      <mass
        value="0.00746769227571282" />
      <inertia
        ixx="1.43700188921078E-07"
        ixy="1.03279061512865E-08"
        ixz="-7.87953197551153E-12"
        iyy="4.30213665771772E-07"
        iyz="-3.63036938017759E-12"
        izz="3.95348120655683E-07" />
    </inertial>
    <visual>
      <origin
        xyz="0 0 0"
        rpy="0 0 0" />
      <geometry>
        <mesh
          filename="package://lizard_description/meshes/RRndServoLink.STL" />
      </geometry>
      <material
        name="">
        <color
          rgba="1 0.949019607843137 0.909803921568627 1" />
      </material>
    </visual>
    <collision>
      <origin
        xyz="0 0 0"
        rpy="0 0 0" />
      <geometry>
        <mesh
          filename="package://lizard_description/meshes/RRndServoLink.STL" />
      </geometry>
    </collision>
  </link>
  <joint
    name="RRndServoJnt"
    type="fixed">
    <origin
      xyz="0.009212 -0.0051538 0.01491"
      rpy="-1.5708 0.9097 1.5827" />
    <parent
      link="RRplateLink" />
    <child
      link="RRndServoLink" />
    <axis
      xyz="0 0 0" />
    <safety_controller
      k_velocity="0" />
  </joint>
  <link
    name="RRstArmLink">
    <inertial>
      <origin
        xyz="0.00400000000000043 -0.0251126471271529 0.0102102199775915"
        rpy="0 0 0" />
      <mass
        value="0.00390389558935974" />
      <inertia
        ixx="1.12495084275856E-06"
        ixy="5.67776772456398E-21"
        ixz="-2.43940051586295E-21"
        iyy="1.95764497849003E-07"
        iyz="3.77530347202475E-07"
        izz="9.70827897862725E-07" />
    </inertial>
    <visual>
      <origin
        xyz="0 0 0"
        rpy="0 0 0" />
      <geometry>
        <mesh
          filename="package://lizard_description/meshes/RRstArmLink.STL" />
      </geometry>
      <material
        name="">
        <color
          rgba="0.917647058823529 0.917647058823529 0.917647058823529 1" />
      </material>
    </visual>
    <collision>
      <origin
        xyz="0 0 0"
        rpy="0 0 0" />
      <geometry>
        <mesh
          filename="package://lizard_description/meshes/RRstArmLink.STL" />
      </geometry>
    </collision>
  </link>
  <joint
    name="RRstArmJnt"
    type="continuous">
    <origin
      xyz="0.00485 0.03105 -0.0061"
      rpy="-3.1416 0 1.5708" />
    <parent
      link="RRndServoLink" />
    <child
      link="RRstArmLink" />
    <axis
      xyz="-1 0 0" />
    <safety_controller
      k_velocity="0" />
  </joint>
  <link
    name="RRrdServoLink">
    <inertial>
      <origin
        xyz="0.00400017767200779 0.00438668430807108 0.0125769879095588"
        rpy="0 0 0" />
      <mass
        value="0.0074676923684259" />
      <inertia
        ixx="3.95348124795591E-07"
        ixy="-7.87921990216771E-12"
        ixz="3.63166363896135E-12"
        iyy="1.43700193125393E-07"
        iyz="-1.03279163798291E-08"
        izz="4.30213663659106E-07" />
    </inertial>
    <visual>
      <origin
        xyz="0 0 0"
        rpy="0 0 0" />
      <geometry>
        <mesh
          filename="package://lizard_description/meshes/RRrdServoLink.STL" />
      </geometry>
      <material
        name="">
        <color
          rgba="1 0.949019607843137 0.909803921568627 1" />
      </material>
    </visual>
    <collision>
      <origin
        xyz="0 0 0"
        rpy="0 0 0" />
      <geometry>
        <mesh
          filename="package://lizard_description/meshes/RRrdServoLink.STL" />
      </geometry>
    </collision>
  </link>
  <joint
    name="RRrdServoJnt"
    type="fixed">
    <origin
      xyz="0.008 -0.05037 0.024797"
      rpy="-1.1846 0 -3.1416" />
    <parent
      link="RRstArmLink" />
    <child
      link="RRrdServoLink" />
    <axis
      xyz="0 0 0" />
    <safety_controller
      k_velocity="0" />
  </joint>
  <link
    name="RRndArmLink">
    <inertial>
      <origin
        xyz="-0.0270688973483293 0.00409999999999987 -0.00147256037884266"
        rpy="0 0 0" />
      <mass
        value="0.00390389558935974" />
      <inertia
        ixx="4.54622043777925E-08"
        ixy="1.02901268201597E-21"
        ixz="-5.86905190678917E-08"
        iyy="1.12495084275856E-06"
        iyz="5.29395592033938E-23"
        izz="1.12113019133394E-06" />
    </inertial>
    <visual>
      <origin
        xyz="0 0 0"
        rpy="0 0 0" />
      <geometry>
        <mesh
          filename="package://lizard_description/meshes/RRndArmLink.STL" />
      </geometry>
      <material
        name="">
        <color
          rgba="0.917647058823529 0.917647058823529 0.917647058823529 1" />
      </material>
    </visual>
    <collision>
      <origin
        xyz="0 0 0"
        rpy="0 0 0" />
      <geometry>
        <mesh
          filename="package://lizard_description/meshes/RRndArmLink.STL" />
      </geometry>
    </collision>
  </link>
  <joint
    name="RRndArmJnt"
    type="continuous">
    <origin
      xyz="0.004 0.00915 0.02665"
      rpy="1.5708 0 -1.5708" />
    <parent
      link="RRrdServoLink" />
    <child
      link="RRndArmLink" />
    <axis
      xyz="0 1 0" />
    <safety_controller
      k_velocity="0" />
  </joint>
  <link
    name="RLstServoLink">
    <inertial>
      <origin
        xyz="0.00982301121173274 0.0100133156629377 0.00609982231678958"
        rpy="0 0 0" />
      <mass
        value="0.00746769221751027" />
      <inertia
        ixx="4.30213637166019E-07"
        ixy="-1.03279487755208E-08"
        ixz="3.62888648014338E-12"
        iyy="1.43700207633304E-07"
        iyz="-7.89258396696791E-12"
        izz="3.9534813702742E-07" />
    </inertial>
    <visual>
      <origin
        xyz="0 0 0"
        rpy="0 0 0" />
      <geometry>
        <mesh
          filename="package://lizard_description/meshes/RLstServoLink.STL" />
      </geometry>
      <material
        name="">
        <color
          rgba="1 0.949019607843137 0.909803921568627 1" />
      </material>
    </visual>
    <collision>
      <origin
        xyz="0 0 0"
        rpy="0 0 0" />
      <geometry>
        <mesh
          filename="package://lizard_description/meshes/RLstServoLink.STL" />
      </geometry>
    </collision>
  </link>
  <joint
    name="RLstServoJnt"
    type="fixed">
    <origin
      xyz="-0.01 0.1 0.015"
      rpy="0 0 -1.5708" />
    <parent
      link="belly" />
    <child
      link="RLstServoLink" />
    <axis
      xyz="0 0 0" />
    <safety_controller
      k_velocity="0" />
  </joint>
  <link
    name="RLplateLink">
    <inertial>
      <origin
        xyz="0.00657919140904437 -0.00649888246337607 0.00332575070540744"
        rpy="0 0 0" />
      <mass
        value="0.00193716814692821" />
      <inertia
        ixx="1.2989349389867E-07"
        ixy="-3.67503145262686E-10"
        ixz="1.88066771707992E-10"
        iyy="6.99558711867067E-08"
        iyz="-1.31536283342677E-09"
        izz="6.80586339434949E-08" />
    </inertial>
    <visual>
      <origin
        xyz="0 0 0"
        rpy="0 0 0" />
      <geometry>
        <mesh
          filename="package://lizard_description/meshes/RLplateLink.STL" />
      </geometry>
      <material
        name="">
        <color
          rgba="0.749019607843137 0.749019607843137 0.749019607843137 1" />
      </material>
    </visual>
    <collision>
      <origin
        xyz="0 0 0"
        rpy="0 0 0" />
      <geometry>
        <mesh
          filename="package://lizard_description/meshes/RLplateLink.STL" />
      </geometry>
    </collision>
  </link>
  <joint
    name="RLplateJnt"
    type="continuous">
    <origin
      xyz="-0.0002 0.00525 0.0061"
      rpy="3.1416 0 3.1416" />
    <parent
      link="RLstServoLink" />
    <child
      link="RLplateLink" />
    <axis
      xyz="1 0 0" />
    <safety_controller
      k_velocity="0" />
  </joint>
  <link
    name="RLndServoLink">
    <inertial>
      <origin
        xyz="0.00961331561995876 0.0168769886979349 0.0060998222122414"
        rpy="0 0 0" />
      <mass
        value="0.00746769306317626" />
      <inertia
        ixx="1.4370019370957E-07"
        ixy="1.03279196726826E-08"
        ixz="-7.8829404499583E-12"
        iyy="4.3021367236017E-07"
        iyz="-3.62992452713935E-12"
        izz="3.95348136263488E-07" />
    </inertial>
    <visual>
      <origin
        xyz="0 0 0"
        rpy="0 0 0" />
      <geometry>
        <mesh
          filename="package://lizard_description/meshes/RLndServoLink.STL" />
      </geometry>
      <material
        name="">
        <color
          rgba="1 0.949019607843137 0.909803921568627 1" />
      </material>
    </visual>
    <collision>
      <origin
        xyz="0 0 0"
        rpy="0 0 0" />
      <geometry>
        <mesh
          filename="package://lizard_description/meshes/RLndServoLink.STL" />
      </geometry>
    </collision>
  </link>
  <joint
    name="RLndServoJnt"
    type="fixed">
    <origin
      xyz="0.00905 -0.012737 -0.0093682"
      rpy="1.5708 -0.3124 1.5708" />
    <parent
      link="RLplateLink" />
    <child
      link="RLndServoLink" />
    <axis
      xyz="0 0 0" />
    <safety_controller
      k_velocity="0" />
  </joint>
  <link
    name="RLstArmLink">
    <inertial>
      <origin
        xyz="-0.0271020769007601 0.00825000000000382 0.000609151367917019"
        rpy="0 0 0" />
      <mass
        value="0.00390389558935974" />
      <inertia
        ixx="4.28157680833787E-08"
        ixy="9.67644152370657E-20"
        ixz="2.4308159164746E-08"
        iyy="1.12495084275856E-06"
        iyz="-2.18697802045689E-21"
        izz="1.12377662762835E-06" />
    </inertial>
    <visual>
      <origin
        xyz="0 0 0"
        rpy="0 0 0" />
      <geometry>
        <mesh
          filename="package://lizard_description/meshes/RLstArmLink.STL" />
      </geometry>
      <material
        name="">
        <color
          rgba="0.917647058823529 0.917647058823529 0.917647058823529 1" />
      </material>
    </visual>
    <collision>
      <origin
        xyz="0 0 0"
        rpy="0 0 0" />
      <geometry>
        <mesh
          filename="package://lizard_description/meshes/RLstArmLink.STL" />
      </geometry>
    </collision>
  </link>
  <joint
    name="RLstArmJnt"
    type="continuous">
    <origin
      xyz="0.00485 0.0268 0.0061"
      rpy="0 0 0" />
    <parent
      link="RLndServoLink" />
    <child
      link="RLstArmLink" />
    <axis
      xyz="0 1 0" />
    <safety_controller
      k_velocity="0" />
  </joint>
  <link
    name="RLrdServoLink">
    <inertial>
      <origin
        xyz="0.00400017757136072 0.0043866842397865 0.0125769884653833"
        rpy="0 0 0" />
      <mass
        value="0.00746769201080103" />
      <inertia
        ixx="3.95348132311498E-07"
        ixy="-7.88895635999624E-12"
        ixz="3.63105731877519E-12"
        iyy="1.43700201041078E-07"
        iyz="-1.03279453992789E-08"
        izz="4.30213632080653E-07" />
    </inertial>
    <visual>
      <origin
        xyz="0 0 0"
        rpy="0 0 0" />
      <geometry>
        <mesh
          filename="package://lizard_description/meshes/RLrdServoLink.STL" />
      </geometry>
      <material
        name="">
        <color
          rgba="1 0.949019607843137 0.909803921568627 1" />
      </material>
    </visual>
    <collision>
      <origin
        xyz="0 0 0"
        rpy="0 0 0" />
      <geometry>
        <mesh
          filename="package://lizard_description/meshes/RLrdServoLink.STL" />
      </geometry>
    </collision>
  </link>
  <joint
    name="RLrdServoJnt"
    type="fixed">
    <origin
      xyz="-0.055896 0.00425 0.0052573"
      rpy="-1.5483 0 1.5708" />
    <parent
      link="RLstArmLink" />
    <child
      link="RLrdServoLink" />
    <axis
      xyz="0 0 0" />
    <safety_controller
      k_velocity="0" />
  </joint>
  <link
    name="RLndArmLink">
    <inertial>
      <origin
        xyz="-0.025570986208634 0.00824999999999998 0.00900101672265811"
        rpy="0 0 0" />
      <mass
        value="0.00390389558935973" />
      <inertia
        ixx="1.61560339778859E-07"
        ixy="-2.06861327587261E-20"
        ixz="3.38893563794123E-07"
        iyy="1.12495084275855E-06"
        iyz="7.17331027205986E-21"
        izz="1.00503205593287E-06" />
    </inertial>
    <visual>
      <origin
        xyz="0 0 0"
        rpy="0 0 0" />
      <geometry>
        <mesh
          filename="package://lizard_description/meshes/RLndArmLink.STL" />
      </geometry>
      <material
        name="">
        <color
          rgba="0.917647058823529 0.917647058823529 0.917647058823529 1" />
      </material>
    </visual>
    <collision>
      <origin
        xyz="0 0 0"
        rpy="0 0 0" />
      <geometry>
        <mesh
          filename="package://lizard_description/meshes/RLndArmLink.STL" />
      </geometry>
    </collision>
  </link>
  <joint
    name="RLndArmJnt"
    type="continuous">
    <origin
      xyz="0.004 0.00915 0.0225"
      rpy="1.5708 0 -1.5708" />
    <parent
      link="RLrdServoLink" />
    <child
      link="RLndArmLink" />
    <axis
      xyz="0 1 0" />
    <safety_controller
      k_velocity="0" />
  </joint>
</robot>